INFO (24/03/2024 03:25:06): Инициализация... (Line: 12) [bot_handler.py]
INFO (24/03/2024 03:25:06): Инициализировано! (Line: 17) [bot_handler.py]
INFO (24/03/2024 03:25:06): Start polling (Line: 527) [dispatcher.py]
INFO (24/03/2024 03:25:07): Run polling for bot @dotabebrabasbot id=6464094470 - 'bebraBot-Test' (Line: 341) [dispatcher.py]
INFO (24/03/2024 03:25:07): Update id=968309464 is not handled. Duration 0 ms by bot id=6464094470 (Line: 172) [dispatcher.py]
INFO (24/03/2024 03:25:07): Update id=968309465 is not handled. Duration 0 ms by bot id=6464094470 (Line: 172) [dispatcher.py]
ERROR (24/03/2024 03:25:07): Cause exception while process update id=968309465 by bot id=6464094470
NameError: name 'bebra_message' is not defined (Line: 315) [dispatcher.py]
Traceback (most recent call last):
  File "C:\Users\Alexandru\AppData\Local\Programs\Python\Python312\Lib\site-packages\aiogram\dispatcher\dispatcher.py", line 309, in _process_update
    response = await self.feed_update(bot, update, **kwargs)
               ^^^^^^^^^^^^^^^^^^^^^^^^^^^^^^^^^^^^^^^^^^^^^
  File "C:\Users\Alexandru\AppData\Local\Programs\Python\Python312\Lib\site-packages\aiogram\dispatcher\dispatcher.py", line 158, in feed_update
    response = await self.update.wrap_outer_middleware(
               ^^^^^^^^^^^^^^^^^^^^^^^^^^^^^^^^^^^^^^^^
  File "C:\Users\Alexandru\AppData\Local\Programs\Python\Python312\Lib\site-packages\aiogram\dispatcher\middlewares\error.py", line 25, in __call__
    return await handler(event, data)
           ^^^^^^^^^^^^^^^^^^^^^^^^^^
  File "C:\Users\Alexandru\AppData\Local\Programs\Python\Python312\Lib\site-packages\aiogram\dispatcher\middlewares\user_context.py", line 27, in __call__
    return await handler(event, data)
           ^^^^^^^^^^^^^^^^^^^^^^^^^^
  File "C:\Users\Alexandru\AppData\Local\Programs\Python\Python312\Lib\site-packages\aiogram\fsm\middleware.py", line 41, in __call__
    return await handler(event, data)
           ^^^^^^^^^^^^^^^^^^^^^^^^^^
  File "C:\Users\Alexandru\AppData\Local\Programs\Python\Python312\Lib\site-packages\aiogram\dispatcher\event\telegram.py", line 121, in trigger
    return await wrapped_inner(event, kwargs)
           ^^^^^^^^^^^^^^^^^^^^^^^^^^^^^^^^^^
  File "C:\Users\Alexandru\AppData\Local\Programs\Python\Python312\Lib\site-packages\aiogram\dispatcher\event\handler.py", line 43, in call
    return await wrapped()
           ^^^^^^^^^^^^^^^
  File "C:\Users\Alexandru\AppData\Local\Programs\Python\Python312\Lib\site-packages\aiogram\dispatcher\dispatcher.py", line 276, in _listen_update
    return await self.propagate_event(update_type=update_type, event=event, **kwargs)
           ^^^^^^^^^^^^^^^^^^^^^^^^^^^^^^^^^^^^^^^^^^^^^^^^^^^^^^^^^^^^^^^^^^^^^^^^^^
  File "C:\Users\Alexandru\AppData\Local\Programs\Python\Python312\Lib\site-packages\aiogram\dispatcher\router.py", line 128, in propagate_event
    return await observer.wrap_outer_middleware(_wrapped, event=event, data=kwargs)
           ^^^^^^^^^^^^^^^^^^^^^^^^^^^^^^^^^^^^^^^^^^^^^^^^^^^^^^^^^^^^^^^^^^^^^^^^
  File "C:\Users\Alexandru\AppData\Local\Programs\Python\Python312\Lib\site-packages\aiogram\dispatcher\router.py", line 123, in _wrapped
    return await self._propagate_event(
           ^^^^^^^^^^^^^^^^^^^^^^^^^^^^
  File "C:\Users\Alexandru\AppData\Local\Programs\Python\Python312\Lib\site-packages\aiogram\dispatcher\router.py", line 148, in _propagate_event
    response = await observer.trigger(event, **kwargs)
               ^^^^^^^^^^^^^^^^^^^^^^^^^^^^^^^^^^^^^^^
  File "C:\Users\Alexandru\AppData\Local\Programs\Python\Python312\Lib\site-packages\aiogram\dispatcher\event\telegram.py", line 121, in trigger
    return await wrapped_inner(event, kwargs)
           ^^^^^^^^^^^^^^^^^^^^^^^^^^^^^^^^^^
  File "C:\Users\Alexandru\AppData\Local\Programs\Python\Python312\Lib\site-packages\aiogram\dispatcher\event\handler.py", line 43, in call
    return await wrapped()
           ^^^^^^^^^^^^^^^
  File "d:\!Projects\Bots\Telegram\bebraBGBot\bot_handler.py", line 41, in bebra
    await bebra_message(message)
          ^^^^^^^^^^^^^
NameError: name 'bebra_message' is not defined
INFO (24/03/2024 03:25:13): Update id=968309466 is not handled. Duration 0 ms by bot id=6464094470 (Line: 172) [dispatcher.py]
ERROR (24/03/2024 03:25:13): Cause exception while process update id=968309466 by bot id=6464094470
NameError: name 'bebra_message' is not defined (Line: 315) [dispatcher.py]
Traceback (most recent call last):
  File "C:\Users\Alexandru\AppData\Local\Programs\Python\Python312\Lib\site-packages\aiogram\dispatcher\dispatcher.py", line 309, in _process_update
    response = await self.feed_update(bot, update, **kwargs)
               ^^^^^^^^^^^^^^^^^^^^^^^^^^^^^^^^^^^^^^^^^^^^^
  File "C:\Users\Alexandru\AppData\Local\Programs\Python\Python312\Lib\site-packages\aiogram\dispatcher\dispatcher.py", line 158, in feed_update
    response = await self.update.wrap_outer_middleware(
               ^^^^^^^^^^^^^^^^^^^^^^^^^^^^^^^^^^^^^^^^
  File "C:\Users\Alexandru\AppData\Local\Programs\Python\Python312\Lib\site-packages\aiogram\dispatcher\middlewares\error.py", line 25, in __call__
    return await handler(event, data)
           ^^^^^^^^^^^^^^^^^^^^^^^^^^
  File "C:\Users\Alexandru\AppData\Local\Programs\Python\Python312\Lib\site-packages\aiogram\dispatcher\middlewares\user_context.py", line 27, in __call__
    return await handler(event, data)
           ^^^^^^^^^^^^^^^^^^^^^^^^^^
  File "C:\Users\Alexandru\AppData\Local\Programs\Python\Python312\Lib\site-packages\aiogram\fsm\middleware.py", line 41, in __call__
    return await handler(event, data)
           ^^^^^^^^^^^^^^^^^^^^^^^^^^
  File "C:\Users\Alexandru\AppData\Local\Programs\Python\Python312\Lib\site-packages\aiogram\dispatcher\event\telegram.py", line 121, in trigger
    return await wrapped_inner(event, kwargs)
           ^^^^^^^^^^^^^^^^^^^^^^^^^^^^^^^^^^
  File "C:\Users\Alexandru\AppData\Local\Programs\Python\Python312\Lib\site-packages\aiogram\dispatcher\event\handler.py", line 43, in call
    return await wrapped()
           ^^^^^^^^^^^^^^^
  File "C:\Users\Alexandru\AppData\Local\Programs\Python\Python312\Lib\site-packages\aiogram\dispatcher\dispatcher.py", line 276, in _listen_update
    return await self.propagate_event(update_type=update_type, event=event, **kwargs)
           ^^^^^^^^^^^^^^^^^^^^^^^^^^^^^^^^^^^^^^^^^^^^^^^^^^^^^^^^^^^^^^^^^^^^^^^^^^
  File "C:\Users\Alexandru\AppData\Local\Programs\Python\Python312\Lib\site-packages\aiogram\dispatcher\router.py", line 128, in propagate_event
    return await observer.wrap_outer_middleware(_wrapped, event=event, data=kwargs)
           ^^^^^^^^^^^^^^^^^^^^^^^^^^^^^^^^^^^^^^^^^^^^^^^^^^^^^^^^^^^^^^^^^^^^^^^^
  File "C:\Users\Alexandru\AppData\Local\Programs\Python\Python312\Lib\site-packages\aiogram\dispatcher\router.py", line 123, in _wrapped
    return await self._propagate_event(
           ^^^^^^^^^^^^^^^^^^^^^^^^^^^^
  File "C:\Users\Alexandru\AppData\Local\Programs\Python\Python312\Lib\site-packages\aiogram\dispatcher\router.py", line 148, in _propagate_event
    response = await observer.trigger(event, **kwargs)
               ^^^^^^^^^^^^^^^^^^^^^^^^^^^^^^^^^^^^^^^
  File "C:\Users\Alexandru\AppData\Local\Programs\Python\Python312\Lib\site-packages\aiogram\dispatcher\event\telegram.py", line 121, in trigger
    return await wrapped_inner(event, kwargs)
           ^^^^^^^^^^^^^^^^^^^^^^^^^^^^^^^^^^
  File "C:\Users\Alexandru\AppData\Local\Programs\Python\Python312\Lib\site-packages\aiogram\dispatcher\event\handler.py", line 43, in call
    return await wrapped()
           ^^^^^^^^^^^^^^^
  File "d:\!Projects\Bots\Telegram\bebraBGBot\bot_handler.py", line 41, in bebra
    await bebra_message(message)
          ^^^^^^^^^^^^^
NameError: name 'bebra_message' is not defined
INFO (24/03/2024 03:26:17): Инициализация... (Line: 13) [bot_handler.py]
INFO (24/03/2024 03:26:17): Инициализировано! (Line: 18) [bot_handler.py]
INFO (24/03/2024 03:26:17): Start polling (Line: 527) [dispatcher.py]
INFO (24/03/2024 03:26:18): Run polling for bot @dotabebrabasbot id=6464094470 - 'bebraBot-Test' (Line: 341) [dispatcher.py]
INFO (24/03/2024 03:26:36): Update id=968309467 is not handled. Duration 0 ms by bot id=6464094470 (Line: 172) [dispatcher.py]
ERROR (24/03/2024 03:26:36): Cause exception while process update id=968309467 by bot id=6464094470
TypeError: 'NoneType' object is not callable (Line: 315) [dispatcher.py]
Traceback (most recent call last):
  File "C:\Users\Alexandru\AppData\Local\Programs\Python\Python312\Lib\site-packages\aiogram\dispatcher\dispatcher.py", line 309, in _process_update
    response = await self.feed_update(bot, update, **kwargs)
               ^^^^^^^^^^^^^^^^^^^^^^^^^^^^^^^^^^^^^^^^^^^^^
  File "C:\Users\Alexandru\AppData\Local\Programs\Python\Python312\Lib\site-packages\aiogram\dispatcher\dispatcher.py", line 158, in feed_update
    response = await self.update.wrap_outer_middleware(
               ^^^^^^^^^^^^^^^^^^^^^^^^^^^^^^^^^^^^^^^^
  File "C:\Users\Alexandru\AppData\Local\Programs\Python\Python312\Lib\site-packages\aiogram\dispatcher\middlewares\error.py", line 25, in __call__
    return await handler(event, data)
           ^^^^^^^^^^^^^^^^^^^^^^^^^^
  File "C:\Users\Alexandru\AppData\Local\Programs\Python\Python312\Lib\site-packages\aiogram\dispatcher\middlewares\user_context.py", line 27, in __call__
    return await handler(event, data)
           ^^^^^^^^^^^^^^^^^^^^^^^^^^
  File "C:\Users\Alexandru\AppData\Local\Programs\Python\Python312\Lib\site-packages\aiogram\fsm\middleware.py", line 41, in __call__
    return await handler(event, data)
           ^^^^^^^^^^^^^^^^^^^^^^^^^^
  File "C:\Users\Alexandru\AppData\Local\Programs\Python\Python312\Lib\site-packages\aiogram\dispatcher\event\telegram.py", line 121, in trigger
    return await wrapped_inner(event, kwargs)
           ^^^^^^^^^^^^^^^^^^^^^^^^^^^^^^^^^^
  File "C:\Users\Alexandru\AppData\Local\Programs\Python\Python312\Lib\site-packages\aiogram\dispatcher\event\handler.py", line 43, in call
    return await wrapped()
           ^^^^^^^^^^^^^^^
  File "C:\Users\Alexandru\AppData\Local\Programs\Python\Python312\Lib\site-packages\aiogram\dispatcher\dispatcher.py", line 276, in _listen_update
    return await self.propagate_event(update_type=update_type, event=event, **kwargs)
           ^^^^^^^^^^^^^^^^^^^^^^^^^^^^^^^^^^^^^^^^^^^^^^^^^^^^^^^^^^^^^^^^^^^^^^^^^^
  File "C:\Users\Alexandru\AppData\Local\Programs\Python\Python312\Lib\site-packages\aiogram\dispatcher\router.py", line 128, in propagate_event
    return await observer.wrap_outer_middleware(_wrapped, event=event, data=kwargs)
           ^^^^^^^^^^^^^^^^^^^^^^^^^^^^^^^^^^^^^^^^^^^^^^^^^^^^^^^^^^^^^^^^^^^^^^^^
  File "C:\Users\Alexandru\AppData\Local\Programs\Python\Python312\Lib\site-packages\aiogram\dispatcher\router.py", line 123, in _wrapped
    return await self._propagate_event(
           ^^^^^^^^^^^^^^^^^^^^^^^^^^^^
  File "C:\Users\Alexandru\AppData\Local\Programs\Python\Python312\Lib\site-packages\aiogram\dispatcher\router.py", line 148, in _propagate_event
    response = await observer.trigger(event, **kwargs)
               ^^^^^^^^^^^^^^^^^^^^^^^^^^^^^^^^^^^^^^^
  File "C:\Users\Alexandru\AppData\Local\Programs\Python\Python312\Lib\site-packages\aiogram\dispatcher\event\telegram.py", line 121, in trigger
    return await wrapped_inner(event, kwargs)
           ^^^^^^^^^^^^^^^^^^^^^^^^^^^^^^^^^^
  File "C:\Users\Alexandru\AppData\Local\Programs\Python\Python312\Lib\site-packages\aiogram\dispatcher\event\handler.py", line 43, in call
    return await wrapped()
           ^^^^^^^^^^^^^^^
  File "d:\!Projects\Bots\Telegram\bebraBGBot\bot_handler.py", line 42, in bebra
    await bebra_message(message)
  File "d:\!Projects\Bots\Telegram\bebraBGBot\commands\bebra.py", line 21, in bebra_message
    await message.photo(photo='AgACAgIAAxkBAAPMZgABJpre-9PZ17lwwAiukPREkCeiAAKT4DEbS6MBSD2ayU5F5mS1AQADAgADeQADNAQ', caption='bebra')
          ^^^^^^^^^^^^^^^^^^^^^^^^^^^^^^^^^^^^^^^^^^^^^^^^^^^^^^^^^^^^^^^^^^^^^^^^^^^^^^^^^^^^^^^^^^^^^^^^^^^^^^^^^^^^^^^^^^^^^^^^^^^
TypeError: 'NoneType' object is not callable
INFO (24/03/2024 03:27:37): Инициализация... (Line: 13) [bot_handler.py]
INFO (24/03/2024 03:27:38): Инициализировано! (Line: 18) [bot_handler.py]
INFO (24/03/2024 03:27:38): Start polling (Line: 527) [dispatcher.py]
INFO (24/03/2024 03:27:38): Run polling for bot @dotabebrabasbot id=6464094470 - 'bebraBot-Test' (Line: 341) [dispatcher.py]
INFO (24/03/2024 03:27:38): Update id=968309468 is not handled. Duration 0 ms by bot id=6464094470 (Line: 172) [dispatcher.py]
ERROR (24/03/2024 03:27:38): Cause exception while process update id=968309468 by bot id=6464094470
TypeError: 'NoneType' object is not callable (Line: 315) [dispatcher.py]
Traceback (most recent call last):
  File "C:\Users\Alexandru\AppData\Local\Programs\Python\Python312\Lib\site-packages\aiogram\dispatcher\dispatcher.py", line 309, in _process_update
    response = await self.feed_update(bot, update, **kwargs)
               ^^^^^^^^^^^^^^^^^^^^^^^^^^^^^^^^^^^^^^^^^^^^^
  File "C:\Users\Alexandru\AppData\Local\Programs\Python\Python312\Lib\site-packages\aiogram\dispatcher\dispatcher.py", line 158, in feed_update
    response = await self.update.wrap_outer_middleware(
               ^^^^^^^^^^^^^^^^^^^^^^^^^^^^^^^^^^^^^^^^
  File "C:\Users\Alexandru\AppData\Local\Programs\Python\Python312\Lib\site-packages\aiogram\dispatcher\middlewares\error.py", line 25, in __call__
    return await handler(event, data)
           ^^^^^^^^^^^^^^^^^^^^^^^^^^
  File "C:\Users\Alexandru\AppData\Local\Programs\Python\Python312\Lib\site-packages\aiogram\dispatcher\middlewares\user_context.py", line 27, in __call__
    return await handler(event, data)
           ^^^^^^^^^^^^^^^^^^^^^^^^^^
  File "C:\Users\Alexandru\AppData\Local\Programs\Python\Python312\Lib\site-packages\aiogram\fsm\middleware.py", line 41, in __call__
    return await handler(event, data)
           ^^^^^^^^^^^^^^^^^^^^^^^^^^
  File "C:\Users\Alexandru\AppData\Local\Programs\Python\Python312\Lib\site-packages\aiogram\dispatcher\event\telegram.py", line 121, in trigger
    return await wrapped_inner(event, kwargs)
           ^^^^^^^^^^^^^^^^^^^^^^^^^^^^^^^^^^
  File "C:\Users\Alexandru\AppData\Local\Programs\Python\Python312\Lib\site-packages\aiogram\dispatcher\event\handler.py", line 43, in call
    return await wrapped()
           ^^^^^^^^^^^^^^^
  File "C:\Users\Alexandru\AppData\Local\Programs\Python\Python312\Lib\site-packages\aiogram\dispatcher\dispatcher.py", line 276, in _listen_update
    return await self.propagate_event(update_type=update_type, event=event, **kwargs)
           ^^^^^^^^^^^^^^^^^^^^^^^^^^^^^^^^^^^^^^^^^^^^^^^^^^^^^^^^^^^^^^^^^^^^^^^^^^
  File "C:\Users\Alexandru\AppData\Local\Programs\Python\Python312\Lib\site-packages\aiogram\dispatcher\router.py", line 128, in propagate_event
    return await observer.wrap_outer_middleware(_wrapped, event=event, data=kwargs)
           ^^^^^^^^^^^^^^^^^^^^^^^^^^^^^^^^^^^^^^^^^^^^^^^^^^^^^^^^^^^^^^^^^^^^^^^^
  File "C:\Users\Alexandru\AppData\Local\Programs\Python\Python312\Lib\site-packages\aiogram\dispatcher\router.py", line 123, in _wrapped
    return await self._propagate_event(
           ^^^^^^^^^^^^^^^^^^^^^^^^^^^^
  File "C:\Users\Alexandru\AppData\Local\Programs\Python\Python312\Lib\site-packages\aiogram\dispatcher\router.py", line 148, in _propagate_event
    response = await observer.trigger(event, **kwargs)
               ^^^^^^^^^^^^^^^^^^^^^^^^^^^^^^^^^^^^^^^
  File "C:\Users\Alexandru\AppData\Local\Programs\Python\Python312\Lib\site-packages\aiogram\dispatcher\event\telegram.py", line 121, in trigger
    return await wrapped_inner(event, kwargs)
           ^^^^^^^^^^^^^^^^^^^^^^^^^^^^^^^^^^
  File "C:\Users\Alexandru\AppData\Local\Programs\Python\Python312\Lib\site-packages\aiogram\dispatcher\event\handler.py", line 43, in call
    return await wrapped()
           ^^^^^^^^^^^^^^^
  File "d:\!Projects\Bots\Telegram\bebraBGBot\bot_handler.py", line 42, in bebra
    await bebra_message(message)
  File "d:\!Projects\Bots\Telegram\bebraBGBot\commands\bebra.py", line 21, in bebra_message
    await message.photo(photo='AgACAgIAAxkBAAPMZgABJpre-9PZ17lwwAiukPREkCeiAAKT4DEbS6MBSD2ayU5F5mS1AQADAgADeQADNAQ', caption='bebra')
          ^^^^^^^^^^^^^^^^^^^^^^^^^^^^^^^^^^^^^^^^^^^^^^^^^^^^^^^^^^^^^^^^^^^^^^^^^^^^^^^^^^^^^^^^^^^^^^^^^^^^^^^^^^^^^^^^^^^^^^^^^^^
TypeError: 'NoneType' object is not callable
INFO (24/03/2024 03:27:42): Update id=968309469 is handled. Duration 280 ms by bot id=6464094470 (Line: 172) [dispatcher.py]
INFO (24/03/2024 03:27:46): Update id=968309470 is handled. Duration 92 ms by bot id=6464094470 (Line: 172) [dispatcher.py]
